<mujoco model="chassis">
    <compiler angle="radian" />
    <asset>
        <mesh name="drive_motor_mount-v4-3" file="meshes/drive_motor_mount-v4-3.stl" scale="0.001 0.001 0.001" />
        <mesh name="base_plate_layer1-v5-1" file="meshes/base_plate_layer1-v5-1.stl" scale="0.001 0.001 0.001" />
        <mesh name="ST3215_Servo_Motor-v1-2" file="meshes/ST3215_Servo_Motor-v1-2.stl" scale="0.001 0.001 0.001" />
        <mesh name="3_8-Hex-Bore-Plastic-VersaHub-217-5828-v2-2" file="meshes/3_8-Hex-Bore-Plastic-VersaHub-217-5828-v2-2.stl" scale="0.001 0.001 0.001" />
        <mesh name="4-Omni-Directional-Wheel_Single_Body-v1-2" file="meshes/simplify_4-Omni-Directional-Wheel_Single_Body-v1-2.stl" scale="0.001 0.001 0.001" />
        <mesh name="drive_motor_mount-v4-2" file="meshes/drive_motor_mount-v4-2.stl" scale="0.001 0.001 0.001" />
        <mesh name="ST3215_Servo_Motor-v1-1" file="meshes/ST3215_Servo_Motor-v1-1.stl" scale="0.001 0.001 0.001" />
        <mesh name="3_8-Hex-Bore-Plastic-VersaHub-217-5828-v2-1" file="meshes/3_8-Hex-Bore-Plastic-VersaHub-217-5828-v2-1.stl" scale="0.001 0.001 0.001" />
        <mesh name="4-Omni-Directional-Wheel_Single_Body-v1-1" file="meshes/simplify_4-Omni-Directional-Wheel_Single_Body-v1-1.stl" scale="0.001 0.001 0.001" />
        <mesh name="drive_motor_mount-v4-1" file="meshes/drive_motor_mount-v4-1.stl" scale="0.001 0.001 0.001" />
        <mesh name="ST3215_Servo_Motor-v1" file="meshes/ST3215_Servo_Motor-v1.stl" scale="0.001 0.001 0.001" />
        <mesh name="3_8-Hex-Bore-Plastic-VersaHub-217-5828-v2" file="meshes/3_8-Hex-Bore-Plastic-VersaHub-217-5828-v2.stl" scale="0.001 0.001 0.001" />
        <mesh name="4-Omni-Directional-Wheel_Single_Body-v1" file="meshes/simplify_4-Omni-Directional-Wheel_Single_Body-v1.stl" scale="0.001 0.001 0.001" />
        <mesh name="servo_controller_mount-v1" file="meshes/servo_controller_mount-v1.stl" scale="0.001 0.001 0.001" />
        <mesh name="lipo_battery_mount-v1" file="meshes/lipo_battery_mount-v1.stl" scale="0.001 0.001 0.001" />
        <mesh name="Battery---Battery-5.2-Ah-DC5521-Plug-v2" file="meshes/Battery---Battery-5.2-Ah-DC5521-Plug-v2.stl" scale="0.001 0.001 0.001" />
        <mesh name="94868A713_NO-THREADS_Female-Threaded-Hex-Standoff" file="meshes/94868A713_NO-THREADS_Female-Threaded-Hex-Standoff.stl" scale="0.001 0.001 0.001" />
        <mesh name="base_plate_layer2-v1" file="meshes/base_plate_layer2-v1.stl" scale="0.001 0.001 0.001" />
        <mesh name="Bottom-V2-v3" file="meshes/Bottom-V2-v3.stl" scale="0.001 0.001 0.001" />
        <mesh name="Top-V2-v2" file="meshes/Top-V2-v2.stl" scale="0.001 0.001 0.001" />
        <mesh name="Camera-Mount-v6" file="meshes/Camera-Mount-v6.stl" scale="0.001 0.001 0.001" />
        <mesh name="Camera-Model-v3" file="meshes/Camera-Model-v3.stl" scale="0.001 0.001 0.001" />
        <mesh name="94868A713_NO-THREADS_Female-Threaded-Hex-Standoff-1" file="meshes/94868A713_NO-THREADS_Female-Threaded-Hex-Standoff-1.stl" scale="0.001 0.001 0.001" />
        <mesh name="94868A713_NO-THREADS_Female-Threaded-Hex-Standoff-2" file="meshes/94868A713_NO-THREADS_Female-Threaded-Hex-Standoff-2.stl" scale="0.001 0.001 0.001" />
        <mesh name="94868A713_NO-THREADS_Female-Threaded-Hex-Standoff-3" file="meshes/94868A713_NO-THREADS_Female-Threaded-Hex-Standoff-3.stl" scale="0.001 0.001 0.001" />
        <mesh name="drive_motor_mount-v4" file="meshes/drive_motor_mount-v4.stl" scale="0.001 0.001 0.001" />
    </asset>

    <default>
        <default class="so_arm100">
            <joint frictionloss="0.1" armature="0.1"/>
            <position kp="50" dampratio="1" forcerange="-35 35" ctrlrange="-3.14158 3.14158"/>
            <default class="visual">
                <geom type="mesh" contype="0" conaffinity="0" density="0" group="2" material="orange"/>
                <default class="motor_visual">
                    <geom material="black"/>
                </default>
            </default>
            <default class="collision">
                <geom group="3" type="mesh"/>
                <default class="finger_collision">
                    <geom type="box" solimp="2 1 0.01" solref="0.01 1" friction="1 0.005 0.0001"/>
                </default>
            </default>
        </default>
    </default>

    <actuator>
        <!-- Base drive motors -->
        <motor name="drive_motor_1" joint="ST3215_Servo_Motor-v1-2_Hub---Servo" gear="1" />
        <motor name="drive_motor_2" joint="ST3215_Servo_Motor-v1-1_Hub-2---Servo" gear="1" />
        <motor name="drive_motor_3" joint="ST3215_Servo_Motor-v1_Revolute-40" gear="1" />
    </actuator>

    <worldbody>
        <light directional="true" pos="-0.5 0.5 3" dir="0 0 -1" />
        <geom pos="0 0 -0.001" size="5 5 0.001" type="plane" rgba="0.8 0.8 0.8 1" />
        <body name="base_plate_layer1-v5-1" pos="0.0 0.0 0.0" euler="-0.0 0.0 -0.0">
            <freejoint name="base_freejoint"/>
            <site name="red_sphere" pos="0 0 0" size="0.01" rgba="1 0 0 1" type="sphere"/>
            <geom name="base_plate_layer1-v5-1_geom" type="mesh" mesh="base_plate_layer1-v5-1" pos="0 0 0" euler="0 0 0" />
            <inertial mass="1.9468624348344596" pos="-4.730687660675253e-15 -2.7155537377808555e-05 -0.0035000000000000005" fullinertia="0.005637109888809055 0.005628440956780792 0.0112496514690387 1.3447333053523504e-16 1.7848833522297417e-20 2.6469779601696886e-23" />
            <body name="drive_motor_mount-v4-3" pos="-0.020610000007450578 -0.09 0.0020000000000000018" euler="-0.0 0.0 -1.5707963267948966">
                <geom name="drive_motor_mount-v4-3_geom" type="mesh" mesh="drive_motor_mount-v4-3" pos="0 0 0" euler="0 0 0" />
                <inertial mass="0.035884017191401885" pos="0.00017900181977195112 -0.0006914486154622601 0.0004348187449640745" fullinertia="3.2235542654871883e-06 3.901284246443171e-06 6.890721819180175e-06 -1.4488185386067676e-08 -3.4701845947883736e-08 1.0877684749210782e-07" />
                <body name="ST3215_Servo_Motor-v1-2" pos="0.00959999999999999 -0.004889999992549421 0.01436" euler="-6.123233995736766e-17 0.0 -1.5707963267948968">
                    <geom name="ST3215_Servo_Motor-v1-2_geom" type="mesh" mesh="ST3215_Servo_Motor-v1-2" pos="0 0 0" euler="0 0 0" />
                    <inertial mass="0.0658962961901927" pos="-0.014664257020729004 -0.008722816656342332 1.2191853053420506e-06" fullinertia="1.0300908387946657e-05 1.3913691655689984e-05 1.8215748982019662e-05 1.1951581712694353e-07 -1.7998869276644268e-09 8.88550145137008e-10" />
                    <body name="3_8-Hex-Bore-Plastic-VersaHub-217-5828-v2-2" pos="-0.025500000000000002 0.011187500000000003 2.220446049250313e-18" euler="-1.5707963267948966 1.5192908393215678e-64 3.141592653589793">
                        <joint name="ST3215_Servo_Motor-v1-2_Hub---Servo" type="hinge" axis="6.887535064975403e-49 -3.749399456654644e-33 1.0" pos="-4.4408920985006255e-18 -3.469446951953615e-18 -0.0015874999999999917" />
                        <geom name="3_8-Hex-Bore-Plastic-VersaHub-217-5828-v2-2_geom" type="mesh" mesh="3_8-Hex-Bore-Plastic-VersaHub-217-5828-v2-2" pos="0 0 0" euler="0 0 0" />
                        <inertial mass="0.08665496109754897" pos="8.50877658112488e-09 7.358945011137765e-09 0.0023811166424899887" fullinertia="1.2296291761641504e-05 1.2296276073121143e-05 2.2911778015411222e-05 -3.19167294920219e-12 1.755992026942528e-12 1.5186622033709633e-12" />
                        <body name="4-Omni-Directional-Wheel_Single_Body-v1-2" pos="-2.453269466693399e-18 0.0 0.0174625" euler="-3.141592653589793 -1.5192908393215678e-64 -0.2617993877991494">
                            <geom name="4-Omni-Directional-Wheel_Single_Body-v1-2_geom" type="mesh" mesh="4-Omni-Directional-Wheel_Single_Body-v1-2" pos="0 0 0" euler="0 0 0" friction="1.0 0.5 0.0001" />
                            <inertial mass="1.3542854082324305" pos="-7.105207895657716e-08 -1.1369917947312704e-07 -1.2090586078983279e-08" fullinertia="0.0010936200374455458 0.0010936108480286116 0.0018798127501507855 -5.245142023675448e-09 4.046730352778215e-10 1.0004485488405523e-10" />
                        </body>
                    </body>
                </body>
            </body>
            <body name="drive_motor_mount-v4-2" pos="0.08824728634432479 0.027151216421550314 0.001999999999999993" euler="-0.0 0.0 0.5235987755982997">
                <geom name="drive_motor_mount-v4-2_geom" type="mesh" mesh="drive_motor_mount-v4-2" pos="0 0 0" euler="0 0 0" />
                <inertial mass="0.035884017191401885" pos="0.00017900181977194513 -0.0006914486154622601 0.00043481874496407525" fullinertia="3.2235542654872044e-06 3.901284246443212e-06 6.890721819180191e-06 -1.4488185386052894e-08 -3.470184594788067e-08 1.0877684749210813e-07" />
                <body name="ST3215_Servo_Motor-v1-1" pos="0.010400000000000081 -0.004889999992549394 0.014359999999999984" euler="-6.406864442435952e-17 -7.857775794700331e-16 -1.570796326794897">
                    <geom name="ST3215_Servo_Motor-v1-1_geom" type="mesh" mesh="ST3215_Servo_Motor-v1-1" pos="0 0 0" euler="0 0 0" />
                    <inertial mass="0.0658962961901927" pos="-0.014664257020728995 -0.008722816656342374 1.2191853053600496e-06" fullinertia="1.0300908387946253e-05 1.391369165569022e-05 1.8215748982019256e-05 1.1951581712706042e-07 -1.7998869276893484e-09 8.885501451146896e-10" />
                    <body name="3_8-Hex-Bore-Plastic-VersaHub-217-5828-v2-1" pos="-0.02550000000000004 0.011187499999999986 0.0" euler="-1.5707963267948966 2.220446049250324e-16 1.6021677874353734e-16">
                        <joint name="ST3215_Servo_Motor-v1-1_Hub-2---Servo" type="hinge" axis="-2.018922194424455e-07 5.551115123125783e-17 0.9999996503124177" pos="1.0279185592260934e-07 6.850769951327593e-18 -0.0015873219592831226" />
                        <geom name="3_8-Hex-Bore-Plastic-VersaHub-217-5828-v2-1_geom" type="mesh" mesh="3_8-Hex-Bore-Plastic-VersaHub-217-5828-v2-1" pos="0 0 0" euler="0 0 0" />
                        <inertial mass="0.08665496109754897" pos="8.508776579152501e-09 7.358945011269938e-09 0.0023811166424899787" fullinertia="1.2296291761641589e-05 1.2296276073121566e-05 2.2911778015411107e-05 -3.1916729680995547e-12 1.755991986238418e-12 1.5186621750295066e-12" />
                        <body name="4-Omni-Directional-Wheel_Single_Body-v1-1" pos="-8.88178419700111e-18 3.3306690738754695e-17 0.01746250000000007" euler="3.141592653589793 5.5511151231257747e-17 1.8325957145940461">
                            <geom name="4-Omni-Directional-Wheel_Single_Body-v1-1_geom" type="mesh" mesh="4-Omni-Directional-Wheel_Single_Body-v1-1" pos="0 0 0" euler="0 0 0" friction="1.0 0.5 0.0001" />
                            <inertial mass="1.3542854082324305" pos="-7.105207896524954e-08 -1.1369917948959942e-07 -1.2090586104095832e-08" fullinertia="0.0010936200374455313 0.0010936108480285981 0.0018798127501507892 -5.2451420243259696e-09 4.0467303541420525e-10 1.0004485627777097e-10" />
                        </body>
                    </body>
                </body>
            </body>
            <body name="drive_motor_mount-v4-1" pos="-0.06763728633687423 0.06284878357844971 0.0020000000000000018" euler="5.415442118703716e-17 -1.3598996028091536e-16 2.617993877991494">
                <geom name="drive_motor_mount-v4-1_geom" type="mesh" mesh="drive_motor_mount-v4-1" pos="0 0 0" euler="0 0 0" />
                <inertial mass="0.035884017191401885" pos="0.0001790018197719455 -0.0006914486154622614 0.0004348187449640748" fullinertia="3.2235542654871925e-06 3.901284246443185e-06 6.890721819180079e-06 -1.4488185386019653e-08 -3.470184594788136e-08 1.087768474921115e-07" />
                <body name="ST3215_Servo_Motor-v1" pos="0.00959999999999999 -0.004889999992549434 0.014360000000000013" euler="2.2863854877850107e-16 -1.2117128698533114e-16 -1.5707963267948966">
                    <geom name="ST3215_Servo_Motor-v1_geom" type="mesh" mesh="ST3215_Servo_Motor-v1" pos="0 0 0" euler="0 0 0" />
                    <inertial mass="0.0658962961901927" pos="-0.014664257020729005 -0.00872281665634233 1.2191853053530741e-06" fullinertia="1.0300908387946575e-05 1.3913691655689957e-05 1.821574898201946e-05 1.1951581712691303e-07 -1.7998869276903668e-09 8.885501451354187e-10" />
                    <body name="3_8-Hex-Bore-Plastic-VersaHub-217-5828-v2" pos="-0.02549999999999999 0.011187500000000003 -8.881784197001253e-18" euler="-1.5707963267948966 2.4155320165495564e-32 1.570796326794897">
                        <joint name="ST3215_Servo_Motor-v1_Revolute-40" type="hinge" axis="-1.2961506867803505e-16 -2.018922189983563e-07 0.9999996503124184" pos="2.796134304347991e-17 1.2953369686987196e-08 -0.0015874775641056748" />
                        <geom name="3_8-Hex-Bore-Plastic-VersaHub-217-5828-v2_geom" type="mesh" mesh="3_8-Hex-Bore-Plastic-VersaHub-217-5828-v2" pos="0 0 0" euler="0 0 0" />
                        <inertial mass="0.08665496109754897" pos="8.508776583007207e-09 7.358945014555165e-09 0.0023811166424899874" fullinertia="1.2296291761641274e-05 1.2296276073121517e-05 2.291177801541124e-05 -3.1916729470190563e-12 1.7559920314671269e-12 1.5186621186676676e-12" />
                        <body name="4-Omni-Directional-Wheel_Single_Body-v1" pos="-2.220446049250313e-18 -7.105427357601001e-17 0.017462499999999947" euler="-3.141592653589793 6.689058043222894e-18 -0.2617993877991494">
                            <geom name="4-Omni-Directional-Wheel_Single_Body-v1_geom" type="mesh" mesh="4-Omni-Directional-Wheel_Single_Body-v1" pos="0 0 0" euler="0 0 0" friction="1.0 0.5 0.0001" />
                            <inertial mass="1.3542854082324305" pos="-7.105207895771595e-08 -1.1369917947234093e-07 -1.2090586101420118e-08" fullinertia="0.0010936200374455356 0.0010936108480285988 0.0018798127501507824 -5.245142023187557e-09 4.046730340142343e-10 1.0004485862393181e-10" />
                        </body>
                    </body>
                </body>
            </body>
            <body name="servo_controller_mount-v1" pos="0.0 0.06 0.0029999999999999983" euler="-0.0 0.0 -0.0">
                <geom name="servo_controller_mount-v1_geom" type="mesh" mesh="servo_controller_mount-v1" pos="0 0 0" euler="0 0 0" />
                <inertial mass="0.06175589411431898" pos="-3.6769132064861433e-14 0.0 -0.0012090515491760903" fullinertia="1.0761471541836937e-05 1.8890192778258753e-05 2.9413765100515303e-05 2.602085214051591e-22 -6.608103581422321e-19 1.6940658945086007e-21" />
            </body>
            <body name="lipo_battery_mount-v1" pos="-0.05 -0.02 0.0" euler="-0.0 0.0 1.5707963267948968">
                <geom name="lipo_battery_mount-v1_geom" type="mesh" mesh="lipo_battery_mount-v1" pos="0 0 0" euler="0 0 0" />
                <inertial mass="0.1653518573066047" pos="-4.0023770071114873e-16 -0.003034408758946965 0.003481111705280585" fullinertia="9.882008372625315e-05 7.479150401991051e-05 0.0001696386060861471 4.0216183619824973e-19 -1.283332239482784e-19 2.263422861539775e-06" />
                <body name="Battery---Battery-5.2-Ah-DC5521-Plug-v2" pos="2.220446049250313e-18 0.036499999999999984 0.003000000000000007" euler="-1.5707963267948966 6.123233995736767e-17 -1.5707963267948966">
                    <geom name="Battery---Battery-5.2-Ah-DC5521-Plug-v2_geom" type="mesh" mesh="Battery---Battery-5.2-Ah-DC5521-Plug-v2" pos="0 0 0" euler="0 0 0" />
                    <inertial mass="1.2215469988184764" pos="0.020000000000000018 -8.300646300726007e-05 -0.03492202423172039" fullinertia="0.0008162228074590446 0.00065975897252246 0.00047597821218279645 1.3010426069826053e-18 4.3368086899420163e-19 3.135378714781114e-06" />
                </body>
            </body>
            <body name="94868A713_NO-THREADS_Female-Threaded-Hex-Standoff" pos="0.0 1.3010426069826053e-18 0.025" euler="-0.0 0.0 -0.0">
                <geom name="94868A713_NO-THREADS_Female-Threaded-Hex-Standoff_geom" type="mesh" mesh="94868A713_NO-THREADS_Female-Threaded-Hex-Standoff" pos="0 0 0" euler="0 0 0" />
                <inertial mass="0.006150070863406618" pos="2.1864399078485972e-14 -1.2010287423717232e-09 -6.6970201384464195e-09" fullinertia="1.0965196650850464e-06 1.096519654894581e-06 1.837396493115053e-08 3.0209076389532564e-20 2.6974127807751317e-18 -9.149560120561933e-14" />
            </body>
            <body name="Camera-Mount-v6" pos="-4.551914400963142e-17 0.1 0.0" euler="-0.0 0.0 1.5707963267948966">
                <geom name="Camera-Mount-v6_geom" type="mesh" mesh="Camera-Mount-v6" pos="0 0 0" euler="0 0 0" />
                <inertial mass="0.09147094298688183" pos="0.0030289224720198397 0.00011242904514014542 0.02064739422580405" fullinertia="3.4924657273467044e-05 1.7958936503269972e-05 1.8461671554877027e-05 -2.8535574628355763e-08 1.483173255618039e-06 1.1115307183257866e-07" />
                <body name="Camera-Model-v3" pos="0.005843306737767851 -6.514592966970533e-17 0.02401122309705938" euler="-9.937525710640365e-31 1.3962634015954634 1.5707963267948966">
                    <geom name="Camera-Model-v3_geom" type="mesh" mesh="Camera-Model-v3" pos="0 0 0" euler="0 0 0" />
                    <inertial mass="0.039920058315088616" pos="0.00011860470791938802 0.00023881874959842783 0.004326318838629241" fullinertia="5.219349028990072e-06 5.305573488496055e-06 7.674281395938296e-06 6.564111916115197e-08 1.3381791184156136e-08 2.6971366213773554e-08" />
                </body>
            </body>
            <body name="94868A713_NO-THREADS_Female-Threaded-Hex-Standoff-1" pos="-0.09660254037844385 0.03267949192431126 0.025" euler="8.164311994315686e-17 0.0 -0.0">
                <geom name="94868A713_NO-THREADS_Female-Threaded-Hex-Standoff-1_geom" type="mesh" mesh="94868A713_NO-THREADS_Female-Threaded-Hex-Standoff-1" pos="0 0 0" euler="0 0 0" />
                <inertial mass="0.006150070863406618" pos="2.1866952693017084e-14 -1.2010287431252216e-09 -6.6970201384464195e-09" fullinertia="1.0965196650850481e-06 1.0965196548945726e-06 1.8373964931137077e-08 3.3881317890172236e-20 2.698646969952201e-18 -9.149560204254155e-14" />
            </body>
            <body name="94868A713_NO-THREADS_Female-Threaded-Hex-Standoff-2" pos="0.02 -0.1 0.025" euler="8.164311994315686e-17 0.0 -0.0">
                <geom name="94868A713_NO-THREADS_Female-Threaded-Hex-Standoff-2_geom" type="mesh" mesh="94868A713_NO-THREADS_Female-Threaded-Hex-Standoff-2" pos="0 0 0" euler="0 0 0" />
                <inertial mass="0.006150070863406618" pos="2.1862511800918584e-14 -1.2010287342434374e-09 -6.6970201384464195e-09" fullinertia="1.096519665085043e-06 1.0965196548945802e-06 1.837396493115063e-08 3.2187251995663636e-20 2.6969529040576923e-18 -9.14956011955086e-14" />
            </body>
            <body name="94868A713_NO-THREADS_Female-Threaded-Hex-Standoff-3" pos="0.0766025403784439 0.06732050807568875 0.025" euler="8.164311994315686e-17 0.0 -0.0">
                <geom name="94868A713_NO-THREADS_Female-Threaded-Hex-Standoff-3_geom" type="mesh" mesh="94868A713_NO-THREADS_Female-Threaded-Hex-Standoff-3" pos="0 0 0" euler="0 0 0" />
                <inertial mass="0.006150070863406618" pos="2.1866952693017084e-14 -1.2010287342434374e-09 -6.6970201384464195e-09" fullinertia="1.096519665085043e-06 1.0965196548945862e-06 1.8373964931164182e-08 2.7105054312137834e-20 2.6969529040576923e-18 -9.149559950144271e-14" />
            </body>
        </body>
        <body name="base_plate_layer2-v1" pos="0.0 -6.430841866638185e-19 0.056999999999999995" euler="-0.0 0.0 -0.0">
            <geom name="base_plate_layer2-v1_geom" type="mesh" mesh="base_plate_layer2-v1" pos="0 0 0" euler="0 0 0" />
            <inertial mass="1.9468624348344596" pos="-4.730687660675253e-15 -2.7155537377808555e-05 -0.0034999999999999966" fullinertia="0.0056371098888090545 0.005628440956780792 0.0112496514690387 1.3447333053523506e-16 1.7848833522266602e-20 0.0" />
            <body name="Bottom-V2-v3" pos="-2.980230284777008e-11 -0.06400000000000002 1.4210854715202004e-16" euler="-2.2293090993986824e-33 9.57182296485495e-19 -3.141592653589793">
                <geom name="Bottom-V2-v3_geom" type="mesh" mesh="Bottom-V2-v3" pos="0 0 0" euler="0 0 0" />
                <inertial mass="0.14588862570926195" pos="-0.00162379917481353 0.0017514442972537737 0.0028600223736592917" fullinertia="5.861212367196976e-05 0.000126485904877694 0.00018209683987627657 1.504419769130799e-06 2.5907710844293906e-06 -7.708271472892189e-07" />
                <body name="Top-V2-v2" pos="-2.2605506554644607e-07 0.0 0.02899957050948762" euler="-3.141592653589793 -9.571822964854947e-19 -5.551115123126053e-17">
                    <geom name="Top-V2-v2_geom" type="mesh" mesh="Top-V2-v2" pos="0 0 0" euler="0 0 0" />
                    <inertial mass="0.1256590419653392" pos="-0.0036436981408919968 -0.0003259633563240798 0.004946871759115404" fullinertia="5.8982381320791524e-05 0.00013338786905954623 0.00018586375094365218 1.6170683703385845e-07 2.7949770042390678e-06 -5.073018525688329e-07" />
                </body>
            </body>
        </body>
        <body name="drive_motor_mount-v4" pos="-0.020610000007450578 -0.09 0.0020000000000000018" euler="-0.0 0.0 -1.5707963267948966">
            <geom name="drive_motor_mount-v4_geom" type="mesh" mesh="drive_motor_mount-v4" pos="0 0 0" euler="0 0 0" />
            <inertial mass="0.035884017191401885" pos="0.00017900181977195112 -0.0006914486154622601 0.0004348187449640745" fullinertia="3.2235542654871883e-06 3.901284246443171e-06 6.890721819180175e-06 -1.4488185386067676e-08 -3.4701845947883736e-08 1.0877684749210782e-07" />
        </body>
    </worldbody>
</mujoco>
        <mesh name="ST3215_Servo_Motor-v1-2" file="meshes/ST3215_Servo_Motor-v1-2.stl" scale="0.001 0.001 0.001" />
        <mesh name="3_8-Hex-Bore-Plastic-VersaHub-217-5828-v2-2" file="meshes/3_8-Hex-Bore-Plastic-VersaHub-217-5828-v2-2.stl" scale="0.001 0.001 0.001" />
        <mesh name="4-Omni-Directional-Wheel_Single_Body-v1-2" file="meshes/simplify_4-Omni-Directional-Wheel_Single_Body-v1-2.stl" scale="0.001 0.001 0.001" />
        <mesh name="drive_motor_mount-v4-2" file="meshes/drive_motor_mount-v4-2.stl" scale="0.001 0.001 0.001" />
        <mesh name="ST3215_Servo_Motor-v1-1" file="meshes/ST3215_Servo_Motor-v1-1.stl" scale="0.001 0.001 0.001" />
        <mesh name="3_8-Hex-Bore-Plastic-VersaHub-217-5828-v2-1" file="meshes/3_8-Hex-Bore-Plastic-VersaHub-217-5828-v2-1.stl" scale="0.001 0.001 0.001" />
        <mesh name="4-Omni-Directional-Wheel_Single_Body-v1-1" file="meshes/simplify_4-Omni-Directional-Wheel_Single_Body-v1-1.stl" scale="0.001 0.001 0.001" />
        <mesh name="drive_motor_mount-v4-1" file="meshes/drive_motor_mount-v4-1.stl" scale="0.001 0.001 0.001" />
        <mesh name="ST3215_Servo_Motor-v1" file="meshes/ST3215_Servo_Motor-v1.stl" scale="0.001 0.001 0.001" />
        <mesh name="3_8-Hex-Bore-Plastic-VersaHub-217-5828-v2" file="meshes/3_8-Hex-Bore-Plastic-VersaHub-217-5828-v2.stl" scale="0.001 0.001 0.001" />
        <mesh name="4-Omni-Directional-Wheel_Single_Body-v1" file="meshes/simplify_4-Omni-Directional-Wheel_Single_Body-v1.stl" scale="0.001 0.001 0.001" />
        <mesh name="servo_controller_mount-v1" file="meshes/servo_controller_mount-v1.stl" scale="0.001 0.001 0.001" />
        <mesh name="lipo_battery_mount-v1" file="meshes/lipo_battery_mount-v1.stl" scale="0.001 0.001 0.001" />
        <mesh name="Battery---Battery-5.2-Ah-DC5521-Plug-v2" file="meshes/Battery---Battery-5.2-Ah-DC5521-Plug-v2.stl" scale="0.001 0.001 0.001" />
        <mesh name="94868A713_NO-THREADS_Female-Threaded-Hex-Standoff" file="meshes/94868A713_NO-THREADS_Female-Threaded-Hex-Standoff.stl" scale="0.001 0.001 0.001" />
        <mesh name="base_plate_layer2-v1" file="meshes/base_plate_layer2-v1.stl" scale="0.001 0.001 0.001" />
        <mesh name="Bottom-V2-v3" file="meshes/Bottom-V2-v3.stl" scale="0.001 0.001 0.001" />
        <mesh name="Top-V2-v2" file="meshes/Top-V2-v2.stl" scale="0.001 0.001 0.001" />
        <mesh name="Camera-Mount-v6" file="meshes/Camera-Mount-v6.stl" scale="0.001 0.001 0.001" />
        <mesh name="Camera-Model-v3" file="meshes/Camera-Model-v3.stl" scale="0.001 0.001 0.001" />
        <mesh name="94868A713_NO-THREADS_Female-Threaded-Hex-Standoff-1" file="meshes/94868A713_NO-THREADS_Female-Threaded-Hex-Standoff-1.stl" scale="0.001 0.001 0.001" />
        <mesh name="94868A713_NO-THREADS_Female-Threaded-Hex-Standoff-2" file="meshes/94868A713_NO-THREADS_Female-Threaded-Hex-Standoff-2.stl" scale="0.001 0.001 0.001" />
        <mesh name="94868A713_NO-THREADS_Female-Threaded-Hex-Standoff-3" file="meshes/94868A713_NO-THREADS_Female-Threaded-Hex-Standoff-3.stl" scale="0.001 0.001 0.001" />
        <mesh name="drive_motor_mount-v4" file="meshes/drive_motor_mount-v4.stl" scale="0.001 0.001 0.001" />
    </asset>

    <default>
        <default class="so_arm100">
            <joint frictionloss="0.1" armature="0.1"/>
            <position kp="50" dampratio="1" forcerange="-35 35" ctrlrange="-3.14158 3.14158"/>
            <default class="visual">
                <geom type="mesh" contype="0" conaffinity="0" density="0" group="2" material="orange"/>
                <default class="motor_visual">
                    <geom material="black"/>
                </default>
            </default>
            <default class="collision">
                <geom group="3" type="mesh"/>
                <default class="finger_collision">
                    <geom type="box" solimp="2 1 0.01" solref="0.01 1" friction="1 0.005 0.0001"/>
                </default>
            </default>
        </default>
    </default>

    <actuator>
        <!-- Base drive motors -->
        <motor name="drive_motor_1" joint="ST3215_Servo_Motor-v1-2_Hub---Servo" gear="1" />
        <motor name="drive_motor_2" joint="ST3215_Servo_Motor-v1-1_Hub-2---Servo" gear="1" />
        <motor name="drive_motor_3" joint="ST3215_Servo_Motor-v1_Revolute-40" gear="1" />
    </actuator>

    <worldbody>
        <light directional="true" pos="-0.5 0.5 3" dir="0 0 -1" />
        <geom pos="0 0 -0.001" size="5 5 0.001" type="plane" rgba="0.8 0.8 0.8 1" friction="1.0 0.5 0.0001"/>
        <body name="base_plate_layer1-v5-1" pos="0.0 0.0 0.0" euler="-0.0 0.0 -0.0">
            <freejoint name="base_freejoint"/>
            <site name="red_sphere" pos="0 0 0" size="0.01" rgba="1 0 0 1" type="sphere"/>
            <geom name="base_plate_layer1-v5-1_geom" type="mesh" mesh="base_plate_layer1-v5-1" pos="0 0 0" euler="0 0 0" />
            <inertial mass="1.9468624348344596" pos="-4.730687660675253e-15 -2.7155537377808555e-05 -0.0035000000000000005" fullinertia="0.005637109888809055 0.005628440956780792 0.0112496514690387 1.3447333053523504e-16 1.7848833522297417e-20 2.6469779601696886e-23" />
            <body name="drive_motor_mount-v4-3" pos="-0.020610000007450578 -0.09 0.0020000000000000018" euler="-0.0 0.0 -1.5707963267948966">
                <geom name="drive_motor_mount-v4-3_geom" type="mesh" mesh="drive_motor_mount-v4-3" pos="0 0 0" euler="0 0 0" />
                <inertial mass="0.035884017191401885" pos="0.00017900181977195112 -0.0006914486154622601 0.0004348187449640745" fullinertia="3.2235542654871883e-06 3.901284246443171e-06 6.890721819180175e-06 -1.4488185386067676e-08 -3.4701845947883736e-08 1.0877684749210782e-07" />
                <body name="ST3215_Servo_Motor-v1-2" pos="0.00959999999999999 -0.004889999992549421 0.01436" euler="-6.123233995736766e-17 0.0 -1.5707963267948968">
                    <geom name="ST3215_Servo_Motor-v1-2_geom" type="mesh" mesh="ST3215_Servo_Motor-v1-2" pos="0 0 0" euler="0 0 0" />
                    <inertial mass="0.0658962961901927" pos="-0.014664257020729004 -0.008722816656342332 1.2191853053420506e-06" fullinertia="1.0300908387946657e-05 1.3913691655689984e-05 1.8215748982019662e-05 1.1951581712694353e-07 -1.7998869276644268e-09 8.88550145137008e-10" />
                    <body name="3_8-Hex-Bore-Plastic-VersaHub-217-5828-v2-2" pos="-0.025500000000000002 0.011187500000000003 2.220446049250313e-18" euler="-1.5707963267948966 1.5192908393215678e-64 3.141592653589793">
                        <joint name="ST3215_Servo_Motor-v1-2_Hub---Servo" type="hinge" axis="6.887535064975403e-49 -3.749399456654644e-33 1.0" pos="-4.4408920985006255e-18 -3.469446951953615e-18 -0.0015874999999999917" />
                        <geom name="3_8-Hex-Bore-Plastic-VersaHub-217-5828-v2-2_geom" type="mesh" mesh="3_8-Hex-Bore-Plastic-VersaHub-217-5828-v2-2" pos="0 0 0" euler="0 0 0" />
                        <inertial mass="0.08665496109754897" pos="8.50877658112488e-09 7.358945011137765e-09 0.0023811166424899887" fullinertia="1.2296291761641504e-05 1.2296276073121143e-05 2.2911778015411222e-05 -3.19167294920219e-12 1.755992026942528e-12 1.5186622033709633e-12" />
                        <body name="4-Omni-Directional-Wheel_Single_Body-v1-2" pos="-2.453269466693399e-18 0.0 0.0174625" euler="-3.141592653589793 -1.5192908393215678e-64 -0.2617993877991494">
                            <geom name="4-Omni-Directional-Wheel_Single_Body-v1-2_geom" type="mesh" mesh="4-Omni-Directional-Wheel_Single_Body-v1-2" pos="0 0 0" euler="0 0 0" friction="1.0 0.5 0.0001"/>
                            <inertial mass="1.3542854082324305" pos="-7.105207895657716e-08 -1.1369917947312704e-07 -1.2090586078983279e-08" fullinertia="0.0010936200374455458 0.0010936108480286116 0.0018798127501507855 -5.245142023675448e-09 4.046730352778215e-10 1.0004485488405523e-10" />
                        </body>
                    </body>
                </body>
            </body>
            <body name="drive_motor_mount-v4-2" pos="0.08824728634432479 0.027151216421550314 0.001999999999999993" euler="-0.0 0.0 0.5235987755982997">
                <geom name="drive_motor_mount-v4-2_geom" type="mesh" mesh="drive_motor_mount-v4-2" pos="0 0 0" euler="0 0 0" />
                <inertial mass="0.035884017191401885" pos="0.00017900181977194513 -0.0006914486154622601 0.00043481874496407525" fullinertia="3.2235542654872044e-06 3.901284246443212e-06 6.890721819180191e-06 -1.4488185386052894e-08 -3.470184594788067e-08 1.0877684749210813e-07" />
                <body name="ST3215_Servo_Motor-v1-1" pos="0.010400000000000081 -0.004889999992549394 0.014359999999999984" euler="-6.406864442435952e-17 -7.857775794700331e-16 -1.570796326794897">
                    <geom name="ST3215_Servo_Motor-v1-1_geom" type="mesh" mesh="ST3215_Servo_Motor-v1-1" pos="0 0 0" euler="0 0 0" />
                    <inertial mass="0.0658962961901927" pos="-0.014664257020728995 -0.008722816656342374 1.2191853053600496e-06" fullinertia="1.0300908387946253e-05 1.391369165569022e-05 1.8215748982019256e-05 1.1951581712706042e-07 -1.7998869276893484e-09 8.885501451146896e-10" />
                    <body name="3_8-Hex-Bore-Plastic-VersaHub-217-5828-v2-1" pos="-0.02550000000000004 0.011187499999999986 0.0" euler="-1.5707963267948966 2.220446049250324e-16 1.6021677874353734e-16">
                        <joint name="ST3215_Servo_Motor-v1-1_Hub-2---Servo" type="hinge" axis="-2.018922194424455e-07 5.551115123125783e-17 0.9999996503124177" pos="1.0279185592260934e-07 6.850769951327593e-18 -0.0015873219592831226" />
                        <geom name="3_8-Hex-Bore-Plastic-VersaHub-217-5828-v2-1_geom" type="mesh" mesh="3_8-Hex-Bore-Plastic-VersaHub-217-5828-v2-1" pos="0 0 0" euler="0 0 0" />
                        <inertial mass="0.08665496109754897" pos="8.508776579152501e-09 7.358945011269938e-09 0.0023811166424899787" fullinertia="1.2296291761641589e-05 1.2296276073121566e-05 2.2911778015411107e-05 -3.1916729680995547e-12 1.755991986238418e-12 1.5186621750295066e-12" />
                        <body name="4-Omni-Directional-Wheel_Single_Body-v1-1" pos="-8.88178419700111e-18 3.3306690738754695e-17 0.01746250000000007" euler="3.141592653589793 5.5511151231257747e-17 1.8325957145940461">
                            <geom name="4-Omni-Directional-Wheel_Single_Body-v1-1_geom" type="mesh" mesh="4-Omni-Directional-Wheel_Single_Body-v1-1" pos="0 0 0" euler="0 0 0" friction="1.0 0.5 0.0001"/>
                            <inertial mass="1.3542854082324305" pos="-7.105207896524954e-08 -1.1369917948959942e-07 -1.2090586104095832e-08" fullinertia="0.0010936200374455313 0.0010936108480285981 0.0018798127501507892 -5.2451420243259696e-09 4.0467303541420525e-10 1.0004485627777097e-10" />
                        </body>
                    </body>
                </body>
            </body>
            <body name="drive_motor_mount-v4-1" pos="-0.06763728633687423 0.06284878357844971 0.0020000000000000018" euler="5.415442118703716e-17 -1.3598996028091536e-16 2.617993877991494">
                <geom name="drive_motor_mount-v4-1_geom" type="mesh" mesh="drive_motor_mount-v4-1" pos="0 0 0" euler="0 0 0" />
                <inertial mass="0.035884017191401885" pos="0.0001790018197719455 -0.0006914486154622614 0.0004348187449640748" fullinertia="3.2235542654871925e-06 3.901284246443185e-06 6.890721819180079e-06 -1.4488185386019653e-08 -3.470184594788136e-08 1.087768474921115e-07" />
                <body name="ST3215_Servo_Motor-v1" pos="0.00959999999999999 -0.004889999992549434 0.014360000000000013" euler="2.2863854877850107e-16 -1.2117128698533114e-16 -1.5707963267948966">
                    <geom name="ST3215_Servo_Motor-v1_geom" type="mesh" mesh="ST3215_Servo_Motor-v1" pos="0 0 0" euler="0 0 0" />
                    <inertial mass="0.0658962961901927" pos="-0.014664257020729005 -0.00872281665634233 1.2191853053530741e-06" fullinertia="1.0300908387946575e-05 1.3913691655689957e-05 1.821574898201946e-05 1.1951581712691303e-07 -1.7998869276903668e-09 8.885501451354187e-10" />
                    <body name="3_8-Hex-Bore-Plastic-VersaHub-217-5828-v2" pos="-0.02549999999999999 0.011187500000000003 -8.881784197001253e-18" euler="-1.5707963267948966 2.4155320165495564e-32 1.570796326794897">
                        <joint name="ST3215_Servo_Motor-v1_Revolute-40" type="hinge" axis="-1.2961506867803505e-16 -2.018922189983563e-07 0.9999996503124184" pos="2.796134304347991e-17 1.2953369686987196e-08 -0.0015874775641056748" />
                        <geom name="3_8-Hex-Bore-Plastic-VersaHub-217-5828-v2_geom" type="mesh" mesh="3_8-Hex-Bore-Plastic-VersaHub-217-5828-v2" pos="0 0 0" euler="0 0 0" />
                        <inertial mass="0.08665496109754897" pos="8.508776583007207e-09 7.358945014555165e-09 0.0023811166424899874" fullinertia="1.2296291761641274e-05 1.2296276073121517e-05 2.291177801541124e-05 -3.1916729470190563e-12 1.7559920314671269e-12 1.5186621186676676e-12" />
                        <body name="4-Omni-Directional-Wheel_Single_Body-v1" pos="-2.220446049250313e-18 -7.105427357601001e-17 0.017462499999999947" euler="-3.141592653589793 6.689058043222894e-18 -0.2617993877991494">
                            <geom name="4-Omni-Directional-Wheel_Single_Body-v1_geom" type="mesh" mesh="4-Omni-Directional-Wheel_Single_Body-v1" pos="0 0 0" euler="0 0 0" friction="1.0 0.5 0.0001"/>
                            <inertial mass="1.3542854082324305" pos="-7.105207895771595e-08 -1.1369917947234093e-07 -1.2090586101420118e-08" fullinertia="0.0010936200374455356 0.0010936108480285988 0.0018798127501507824 -5.245142023187557e-09 4.046730340142343e-10 1.0004485862393181e-10" />
                        </body>
                    </body>
                </body>
            </body>
            <body name="servo_controller_mount-v1" pos="0.0 0.06 0.0029999999999999983" euler="-0.0 0.0 -0.0">
                <geom name="servo_controller_mount-v1_geom" type="mesh" mesh="servo_controller_mount-v1" pos="0 0 0" euler="0 0 0" />
                <inertial mass="0.06175589411431898" pos="-3.6769132064861433e-14 0.0 -0.0012090515491760903" fullinertia="1.0761471541836937e-05 1.8890192778258753e-05 2.9413765100515303e-05 2.602085214051591e-22 -6.608103581422321e-19 1.6940658945086007e-21" />
            </body>
            <body name="lipo_battery_mount-v1" pos="-0.05 -0.02 0.0" euler="-0.0 0.0 1.5707963267948968">
                <geom name="lipo_battery_mount-v1_geom" type="mesh" mesh="lipo_battery_mount-v1" pos="0 0 0" euler="0 0 0" />
                <inertial mass="0.1653518573066047" pos="-4.0023770071114873e-16 -0.003034408758946965 0.003481111705280585" fullinertia="9.882008372625315e-05 7.479150401991051e-05 0.0001696386060861471 4.0216183619824973e-19 -1.283332239482784e-19 2.263422861539775e-06" />
                <body name="Battery---Battery-5.2-Ah-DC5521-Plug-v2" pos="2.220446049250313e-18 0.036499999999999984 0.003000000000000007" euler="-1.5707963267948966 6.123233995736767e-17 -1.5707963267948966">
                    <geom name="Battery---Battery-5.2-Ah-DC5521-Plug-v2_geom" type="mesh" mesh="Battery---Battery-5.2-Ah-DC5521-Plug-v2" pos="0 0 0" euler="0 0 0" />
                    <inertial mass="1.2215469988184764" pos="0.020000000000000018 -8.300646300726007e-05 -0.03492202423172039" fullinertia="0.0008162228074590446 0.00065975897252246 0.00047597821218279645 1.3010426069826053e-18 4.3368086899420163e-19 3.135378714781114e-06" />
                </body>
            </body>
            <body name="94868A713_NO-THREADS_Female-Threaded-Hex-Standoff" pos="0.0 1.3010426069826053e-18 0.025" euler="-0.0 0.0 -0.0">
                <geom name="94868A713_NO-THREADS_Female-Threaded-Hex-Standoff_geom" type="mesh" mesh="94868A713_NO-THREADS_Female-Threaded-Hex-Standoff" pos="0 0 0" euler="0 0 0" />
                <inertial mass="0.006150070863406618" pos="2.1864399078485972e-14 -1.2010287423717232e-09 -6.6970201384464195e-09" fullinertia="1.0965196650850464e-06 1.096519654894581e-06 1.837396493115053e-08 3.0209076389532564e-20 2.6974127807751317e-18 -9.149560120561933e-14" />
            </body>
            <body name="Camera-Mount-v6" pos="-4.551914400963142e-17 0.1 0.0" euler="-0.0 0.0 1.5707963267948966">
                <geom name="Camera-Mount-v6_geom" type="mesh" mesh="Camera-Mount-v6" pos="0 0 0" euler="0 0 0" />
                <inertial mass="0.09147094298688183" pos="0.0030289224720198397 0.00011242904514014542 0.02064739422580405" fullinertia="3.4924657273467044e-05 1.7958936503269972e-05 1.8461671554877027e-05 -2.8535574628355763e-08 1.483173255618039e-06 1.1115307183257866e-07" />
                <body name="Camera-Model-v3" pos="0.005843306737767851 -6.514592966970533e-17 0.02401122309705938" euler="-9.937525710640365e-31 1.3962634015954634 1.5707963267948966">
                    <geom name="Camera-Model-v3_geom" type="mesh" mesh="Camera-Model-v3" pos="0 0 0" euler="0 0 0" />
                    <inertial mass="0.039920058315088616" pos="0.00011860470791938802 0.00023881874959842783 0.004326318838629241" fullinertia="5.219349028990072e-06 5.305573488496055e-06 7.674281395938296e-06 6.564111916115197e-08 1.3381791184156136e-08 2.6971366213773554e-08" />
                </body>
            </body>
            <body name="94868A713_NO-THREADS_Female-Threaded-Hex-Standoff-1" pos="-0.09660254037844385 0.03267949192431126 0.025" euler="8.164311994315686e-17 0.0 -0.0">
                <geom name="94868A713_NO-THREADS_Female-Threaded-Hex-Standoff-1_geom" type="mesh" mesh="94868A713_NO-THREADS_Female-Threaded-Hex-Standoff-1" pos="0 0 0" euler="0 0 0" />
                <inertial mass="0.006150070863406618" pos="2.1866952693017084e-14 -1.2010287431252216e-09 -6.6970201384464195e-09" fullinertia="1.0965196650850481e-06 1.0965196548945726e-06 1.8373964931137077e-08 3.3881317890172236e-20 2.698646969952201e-18 -9.149560204254155e-14" />
            </body>
            <body name="94868A713_NO-THREADS_Female-Threaded-Hex-Standoff-2" pos="0.02 -0.1 0.025" euler="8.164311994315686e-17 0.0 -0.0">
                <geom name="94868A713_NO-THREADS_Female-Threaded-Hex-Standoff-2_geom" type="mesh" mesh="94868A713_NO-THREADS_Female-Threaded-Hex-Standoff-2" pos="0 0 0" euler="0 0 0" />
                <inertial mass="0.006150070863406618" pos="2.1862511800918584e-14 -1.2010287342434374e-09 -6.6970201384464195e-09" fullinertia="1.096519665085043e-06 1.0965196548945802e-06 1.837396493115063e-08 3.2187251995663636e-20 2.6969529040576923e-18 -9.14956011955086e-14" />
            </body>
            <body name="94868A713_NO-THREADS_Female-Threaded-Hex-Standoff-3" pos="0.0766025403784439 0.06732050807568875 0.025" euler="8.164311994315686e-17 0.0 -0.0">
                <geom name="94868A713_NO-THREADS_Female-Threaded-Hex-Standoff-3_geom" type="mesh" mesh="94868A713_NO-THREADS_Female-Threaded-Hex-Standoff-3" pos="0 0 0" euler="0 0 0" />
                <inertial mass="0.006150070863406618" pos="2.1866952693017084e-14 -1.2010287342434374e-09 -6.6970201384464195e-09" fullinertia="1.096519665085043e-06 1.0965196548945862e-06 1.8373964931164182e-08 2.7105054312137834e-20 2.6969529040576923e-18 -9.149559950144271e-14" />
            </body>
        </body>
        <body name="base_plate_layer2-v1" pos="0.0 -6.430841866638185e-19 0.056999999999999995" euler="-0.0 0.0 -0.0">
            <geom name="base_plate_layer2-v1_geom" type="mesh" mesh="base_plate_layer2-v1" pos="0 0 0" euler="0 0 0" />
            <inertial mass="1.9468624348344596" pos="-4.730687660675253e-15 -2.7155537377808555e-05 -0.0034999999999999966" fullinertia="0.0056371098888090545 0.005628440956780792 0.0112496514690387 1.3447333053523506e-16 1.7848833522266602e-20 0.0" />
            <body name="Bottom-V2-v3" pos="-2.980230284777008e-11 -0.06400000000000002 1.4210854715202004e-16" euler="-2.2293090993986824e-33 9.57182296485495e-19 -3.141592653589793">
                <geom name="Bottom-V2-v3_geom" type="mesh" mesh="Bottom-V2-v3" pos="0 0 0" euler="0 0 0" />
                <inertial mass="0.14588862570926195" pos="-0.00162379917481353 0.0017514442972537737 0.0028600223736592917" fullinertia="5.861212367196976e-05 0.000126485904877694 0.00018209683987627657 1.504419769130799e-06 2.5907710844293906e-06 -7.708271472892189e-07" />
                <body name="Top-V2-v2" pos="-2.2605506554644607e-07 0.0 0.02899957050948762" euler="-3.141592653589793 -9.571822964854947e-19 -5.551115123126053e-17">
                    <geom name="Top-V2-v2_geom" type="mesh" mesh="Top-V2-v2" pos="0 0 0" euler="0 0 0" />
                    <inertial mass="0.1256590419653392" pos="-0.0036436981408919968 -0.0003259633563240798 0.004946871759115404" fullinertia="5.8982381320791524e-05 0.00013338786905954623 0.00018586375094365218 1.6170683703385845e-07 2.7949770042390678e-06 -5.073018525688329e-07" />
                </body>
            </body>
        </body>
        <body name="drive_motor_mount-v4" pos="-0.020610000007450578 -0.09 0.0020000000000000018" euler="-0.0 0.0 -1.5707963267948966">
            <geom name="drive_motor_mount-v4_geom" type="mesh" mesh="drive_motor_mount-v4" pos="0 0 0" euler="0 0 0" />
            <inertial mass="0.035884017191401885" pos="0.00017900181977195112 -0.0006914486154622601 0.0004348187449640745" fullinertia="3.2235542654871883e-06 3.901284246443171e-06 6.890721819180175e-06 -1.4488185386067676e-08 -3.4701845947883736e-08 1.0877684749210782e-07" />
        </body>
    </worldbody>
</mujoco><mujoco model="chassis">
    <compiler angle="radian" />
    <asset>
        <mesh name="drive_motor_mount-v4-3" file="meshes/drive_motor_mount-v4-3.stl" scale="0.001 0.001 0.001" />
        <mesh name="base_plate_layer1-v5-1" file="meshes/base_plate_layer1-v5-1.stl" scale="0.001 0.001 0.001" />
        <mesh name="ST3215_Servo_Motor-v1-2" file="meshes/ST3215_Servo_Motor-v1-2.stl" scale="0.001 0.001 0.001" />
        <mesh name="3_8-Hex-Bore-Plastic-VersaHub-217-5828-v2-2" file="meshes/3_8-Hex-Bore-Plastic-VersaHub-217-5828-v2-2.stl" scale="0.001 0.001 0.001" />
        <mesh name="4-Omni-Directional-Wheel_Single_Body-v1-2" file="meshes/simplify_4-Omni-Directional-Wheel_Single_Body-v1-2.stl" scale="0.001 0.001 0.001" />
        <mesh name="drive_motor_mount-v4-2" file="meshes/drive_motor_mount-v4-2.stl" scale="0.001 0.001 0.001" />
        <mesh name="ST3215_Servo_Motor-v1-1" file="meshes/ST3215_Servo_Motor-v1-1.stl" scale="0.001 0.001 0.001" />
        <mesh name="3_8-Hex-Bore-Plastic-VersaHub-217-5828-v2-1" file="meshes/3_8-Hex-Bore-Plastic-VersaHub-217-5828-v2-1.stl" scale="0.001 0.001 0.001" />
        <mesh name="4-Omni-Directional-Wheel_Single_Body-v1-1" file="meshes/simplify_4-Omni-Directional-Wheel_Single_Body-v1-1.stl" scale="0.001 0.001 0.001" />
        <mesh name="drive_motor_mount-v4-1" file="meshes/drive_motor_mount-v4-1.stl" scale="0.001 0.001 0.001" />
        <mesh name="ST3215_Servo_Motor-v1" file="meshes/ST3215_Servo_Motor-v1.stl" scale="0.001 0.001 0.001" />
        <mesh name="3_8-Hex-Bore-Plastic-VersaHub-217-5828-v2" file="meshes/3_8-Hex-Bore-Plastic-VersaHub-217-5828-v2.stl" scale="0.001 0.001 0.001" />
        <mesh name="4-Omni-Directional-Wheel_Single_Body-v1" file="meshes/simplify_4-Omni-Directional-Wheel_Single_Body-v1.stl" scale="0.001 0.001 0.001" />
        <mesh name="servo_controller_mount-v1" file="meshes/servo_controller_mount-v1.stl" scale="0.001 0.001 0.001" />
        <mesh name="lipo_battery_mount-v1" file="meshes/lipo_battery_mount-v1.stl" scale="0.001 0.001 0.001" />
        <mesh name="Battery---Battery-5.2-Ah-DC5521-Plug-v2" file="meshes/Battery---Battery-5.2-Ah-DC5521-Plug-v2.stl" scale="0.001 0.001 0.001" />
        <mesh name="94868A713_NO-THREADS_Female-Threaded-Hex-Standoff" file="meshes/94868A713_NO-THREADS_Female-Threaded-Hex-Standoff.stl" scale="0.001 0.001 0.001" />
        <mesh name="base_plate_layer2-v1" file="meshes/base_plate_layer2-v1.stl" scale="0.001 0.001 0.001" />
        <mesh name="Bottom-V2-v3" file="meshes/Bottom-V2-v3.stl" scale="0.001 0.001 0.001" />
        <mesh name="Top-V2-v2" file="meshes/Top-V2-v2.stl" scale="0.001 0.001 0.001" />
        <mesh name="Camera-Mount-v6" file="meshes/Camera-Mount-v6.stl" scale="0.001 0.001 0.001" />
        <mesh name="Camera-Model-v3" file="meshes/Camera-Model-v3.stl" scale="0.001 0.001 0.001" />
        <mesh name="94868A713_NO-THREADS_Female-Threaded-Hex-Standoff-1" file="meshes/94868A713_NO-THREADS_Female-Threaded-Hex-Standoff-1.stl" scale="0.001 0.001 0.001" />
        <mesh name="94868A713_NO-THREADS_Female-Threaded-Hex-Standoff-2" file="meshes/94868A713_NO-THREADS_Female-Threaded-Hex-Standoff-2.stl" scale="0.001 0.001 0.001" />
        <mesh name="94868A713_NO-THREADS_Female-Threaded-Hex-Standoff-3" file="meshes/94868A713_NO-THREADS_Female-Threaded-Hex-Standoff-3.stl" scale="0.001 0.001 0.001" />
        <mesh name="drive_motor_mount-v4" file="meshes/drive_motor_mount-v4.stl" scale="0.001 0.001 0.001" />
    </asset>

    <default>
        <default class="so_arm100">
            <joint frictionloss="0.1" armature="0.1"/>
            <position kp="50" dampratio="1" forcerange="-35 35" ctrlrange="-3.14158 3.14158"/>
            <default class="visual">
                <geom type="mesh" contype="0" conaffinity="0" density="0" group="2" material="orange"/>
                <default class="motor_visual">
                    <geom material="black"/>
                </default>
            </default>
            <default class="collision">
                <geom group="3" type="mesh"/>
                <default class="finger_collision">
                    <geom type="box" solimp="2 1 0.01" solref="0.01 1" friction="1 0.005 0.0001"/>
                </default>
            </default>
        </default>
    </default>

    <actuator>
        <!-- Base drive motors -->
        <motor name="drive_motor_1" joint="ST3215_Servo_Motor-v1-2_Hub---Servo" gear="1" />
        <motor name="drive_motor_2" joint="ST3215_Servo_Motor-v1-1_Hub-2---Servo" gear="1" />
        <motor name="drive_motor_3" joint="ST3215_Servo_Motor-v1_Revolute-40" gear="1" />
    </actuator>

    <worldbody>
        <light directional="true" pos="-0.5 0.5 3" dir="0 0 -1" />
        <geom pos="0 0 -0.001" size="5 5 0.001" type="plane" rgba="0.8 0.8 0.8 1" friction="1.0 0.5 0.0001"/>
        <body name="base_plate_layer1-v5-1" pos="0.0 0.0 0.0" euler="-0.0 0.0 -0.0">
            <freejoint name="base_freejoint"/>
            <site name="red_sphere" pos="0 0 0" size="0.01" rgba="1 0 0 1" type="sphere"/>
            <geom name="base_plate_layer1-v5-1_geom" type="mesh" mesh="base_plate_layer1-v5-1" pos="0 0 0" euler="0 0 0" />
            <inertial mass="1.9468624348344596" pos="-4.730687660675253e-15 -2.7155537377808555e-05 -0.0035000000000000005" fullinertia="0.005637109888809055 0.005628440956780792 0.0112496514690387 1.3447333053523504e-16 1.7848833522297417e-20 2.6469779601696886e-23" />
            <body name="drive_motor_mount-v4-3" pos="-0.020610000007450578 -0.09 0.0020000000000000018" euler="-0.0 0.0 -1.5707963267948966">
                <geom name="drive_motor_mount-v4-3_geom" type="mesh" mesh="drive_motor_mount-v4-3" pos="0 0 0" euler="0 0 0" />
                <inertial mass="0.035884017191401885" pos="0.00017900181977195112 -0.0006914486154622601 0.0004348187449640745" fullinertia="3.2235542654871883e-06 3.901284246443171e-06 6.890721819180175e-06 -1.4488185386067676e-08 -3.4701845947883736e-08 1.0877684749210782e-07" />
                <body name="ST3215_Servo_Motor-v1-2" pos="0.00959999999999999 -0.004889999992549421 0.01436" euler="-6.123233995736766e-17 0.0 -1.5707963267948968">
                    <geom name="ST3215_Servo_Motor-v1-2_geom" type="mesh" mesh="ST3215_Servo_Motor-v1-2" pos="0 0 0" euler="0 0 0" />
                    <inertial mass="0.0658962961901927" pos="-0.014664257020729004 -0.008722816656342332 1.2191853053420506e-06" fullinertia="1.0300908387946657e-05 1.3913691655689984e-05 1.8215748982019662e-05 1.1951581712694353e-07 -1.7998869276644268e-09 8.88550145137008e-10" />
                    <body name="3_8-Hex-Bore-Plastic-VersaHub-217-5828-v2-2" pos="-0.025500000000000002 0.011187500000000003 2.220446049250313e-18" euler="-1.5707963267948966 1.5192908393215678e-64 3.141592653589793">
                        <joint name="ST3215_Servo_Motor-v1-2_Hub---Servo" type="hinge" axis="6.887535064975403e-49 -3.749399456654644e-33 1.0" pos="-4.4408920985006255e-18 -3.469446951953615e-18 -0.0015874999999999917" />
                        <geom name="3_8-Hex-Bore-Plastic-VersaHub-217-5828-v2-2_geom" type="mesh" mesh="3_8-Hex-Bore-Plastic-VersaHub-217-5828-v2-2" pos="0 0 0" euler="0 0 0" />
                        <inertial mass="0.08665496109754897" pos="8.50877658112488e-09 7.358945011137765e-09 0.0023811166424899887" fullinertia="1.2296291761641504e-05 1.2296276073121143e-05 2.2911778015411222e-05 -3.19167294920219e-12 1.755992026942528e-12 1.5186622033709633e-12" />
                        <body name="4-Omni-Directional-Wheel_Single_Body-v1-2" pos="-2.453269466693399e-18 0.0 0.0174625" euler="-3.141592653589793 -1.5192908393215678e-64 -0.2617993877991494">
                            <geom name="4-Omni-Directional-Wheel_Single_Body-v1-2_geom" type="mesh" mesh="4-Omni-Directional-Wheel_Single_Body-v1-2" pos="0 0 0" euler="0 0 0" friction="1.0 0.5 0.0001" />
                            <inertial mass="1.3542854082324305" pos="-7.105207895657716e-08 -1.1369917947312704e-07 -1.2090586078983279e-08" fullinertia="0.0010936200374455458 0.0010936108480286116 0.0018798127501507855 -5.245142023675448e-09 4.046730352778215e-10 1.0004485488405523e-10" />
                        </body>
                    </body>
                </body>
            </body>
            <body name="drive_motor_mount-v4-2" pos="0.08824728634432479 0.027151216421550314 0.001999999999999993" euler="-0.0 0.0 0.5235987755982997">
                <geom name="drive_motor_mount-v4-2_geom" type="mesh" mesh="drive_motor_mount-v4-2" pos="0 0 0" euler="0 0 0" />
                <inertial mass="0.035884017191401885" pos="0.00017900181977194513 -0.0006914486154622601 0.00043481874496407525" fullinertia="3.2235542654872044e-06 3.901284246443212e-06 6.890721819180191e-06 -1.4488185386052894e-08 -3.470184594788067e-08 1.0877684749210813e-07" />
                <body name="ST3215_Servo_Motor-v1-1" pos="0.010400000000000081 -0.004889999992549394 0.014359999999999984" euler="-6.406864442435952e-17 -7.857775794700331e-16 -1.570796326794897">
                    <geom name="ST3215_Servo_Motor-v1-1_geom" type="mesh" mesh="ST3215_Servo_Motor-v1-1" pos="0 0 0" euler="0 0 0" />
                    <inertial mass="0.0658962961901927" pos="-0.014664257020728995 -0.008722816656342374 1.2191853053600496e-06" fullinertia="1.0300908387946253e-05 1.391369165569022e-05 1.8215748982019256e-05 1.1951581712706042e-07 -1.7998869276893484e-09 8.885501451146896e-10" />
                    <body name="3_8-Hex-Bore-Plastic-VersaHub-217-5828-v2-1" pos="-0.02550000000000004 0.011187499999999986 0.0" euler="-1.5707963267948966 2.220446049250324e-16 1.6021677874353734e-16">
                        <joint name="ST3215_Servo_Motor-v1-1_Hub-2---Servo" type="hinge" axis="-2.018922194424455e-07 5.551115123125783e-17 0.9999996503124177" pos="1.0279185592260934e-07 6.850769951327593e-18 -0.0015873219592831226" />
                        <geom name="3_8-Hex-Bore-Plastic-VersaHub-217-5828-v2-1_geom" type="mesh" mesh="3_8-Hex-Bore-Plastic-VersaHub-217-5828-v2-1" pos="0 0 0" euler="0 0 0" />
                        <inertial mass="0.08665496109754897" pos="8.508776579152501e-09 7.358945011269938e-09 0.0023811166424899787" fullinertia="1.2296291761641589e-05 1.2296276073121566e-05 2.2911778015411107e-05 -3.1916729680995547e-12 1.755991986238418e-12 1.5186621750295066e-12" />
                        <body name="4-Omni-Directional-Wheel_Single_Body-v1-1" pos="-8.88178419700111e-18 3.3306690738754695e-17 0.01746250000000007" euler="3.141592653589793 5.5511151231257747e-17 1.8325957145940461">
                            <geom name="4-Omni-Directional-Wheel_Single_Body-v1-1_geom" type="mesh" mesh="4-Omni-Directional-Wheel_Single_Body-v1-1" pos="0 0 0" euler="0 0 0" friction="1.0 0.5 0.0001" />
                            <inertial mass="1.3542854082324305" pos="-7.105207896524954e-08 -1.1369917948959942e-07 -1.2090586104095832e-08" fullinertia="0.0010936200374455313 0.0010936108480285981 0.0018798127501507892 -5.2451420243259696e-09 4.0467303541420525e-10 1.0004485627777097e-10" />
                        </body>
                    </body>
                </body>
            </body>
            <body name="drive_motor_mount-v4-1" pos="-0.06763728633687423 0.06284878357844971 0.0020000000000000018" euler="5.415442118703716e-17 -1.3598996028091536e-16 2.617993877991494">
                <geom name="drive_motor_mount-v4-1_geom" type="mesh" mesh="drive_motor_mount-v4-1" pos="0 0 0" euler="0 0 0" />
                <inertial mass="0.035884017191401885" pos="0.0001790018197719455 -0.0006914486154622614 0.0004348187449640748" fullinertia="3.2235542654871925e-06 3.901284246443185e-06 6.890721819180079e-06 -1.4488185386019653e-08 -3.470184594788136e-08 1.087768474921115e-07" />
                <body name="ST3215_Servo_Motor-v1" pos="0.00959999999999999 -0.004889999992549434 0.014360000000000013" euler="2.2863854877850107e-16 -1.2117128698533114e-16 -1.5707963267948966">
                    <geom name="ST3215_Servo_Motor-v1_geom" type="mesh" mesh="ST3215_Servo_Motor-v1" pos="0 0 0" euler="0 0 0" />
                    <inertial mass="0.0658962961901927" pos="-0.014664257020729005 -0.00872281665634233 1.2191853053530741e-06" fullinertia="1.0300908387946575e-05 1.3913691655689957e-05 1.821574898201946e-05 1.1951581712691303e-07 -1.7998869276903668e-09 8.885501451354187e-10" />
                    <body name="3_8-Hex-Bore-Plastic-VersaHub-217-5828-v2" pos="-0.02549999999999999 0.011187500000000003 -8.881784197001253e-18" euler="-1.5707963267948966 2.4155320165495564e-32 1.570796326794897">
                        <joint name="ST3215_Servo_Motor-v1_Revolute-40" type="hinge" axis="-1.2961506867803505e-16 -2.018922189983563e-07 0.9999996503124184" pos="2.796134304347991e-17 1.2953369686987196e-08 -0.0015874775641056748" />
                        <geom name="3_8-Hex-Bore-Plastic-VersaHub-217-5828-v2_geom" type="mesh" mesh="3_8-Hex-Bore-Plastic-VersaHub-217-5828-v2" pos="0 0 0" euler="0 0 0" />
                        <inertial mass="0.08665496109754897" pos="8.508776583007207e-09 7.358945014555165e-09 0.0023811166424899874" fullinertia="1.2296291761641274e-05 1.2296276073121517e-05 2.291177801541124e-05 -3.1916729470190563e-12 1.7559920314671269e-12 1.5186621186676676e-12" />
                        <body name="4-Omni-Directional-Wheel_Single_Body-v1" pos="-2.220446049250313e-18 -7.105427357601001e-17 0.017462499999999947" euler="-3.141592653589793 6.689058043222894e-18 -0.2617993877991494">
                            <geom name="4-Omni-Directional-Wheel_Single_Body-v1_geom" type="mesh" mesh="4-Omni-Directional-Wheel_Single_Body-v1" pos="0 0 0" euler="0 0 0" friction="1.0 0.5 0.0001" />
                            <inertial mass="1.3542854082324305" pos="-7.105207895771595e-08 -1.1369917947234093e-07 -1.2090586101420118e-08" fullinertia="0.0010936200374455356 0.0010936108480285988 0.0018798127501507824 -5.245142023187557e-09 4.046730340142343e-10 1.0004485862393181e-10" />
                        </body>
                    </body>
                </body>
            </body>
            <body name="servo_controller_mount-v1" pos="0.0 0.06 0.0029999999999999983" euler="-0.0 0.0 -0.0">
                <geom name="servo_controller_mount-v1_geom" type="mesh" mesh="servo_controller_mount-v1" pos="0 0 0" euler="0 0 0" />
                <inertial mass="0.06175589411431898" pos="-3.6769132064861433e-14 0.0 -0.0012090515491760903" fullinertia="1.0761471541836937e-05 1.8890192778258753e-05 2.9413765100515303e-05 2.602085214051591e-22 -6.608103581422321e-19 1.6940658945086007e-21" />
            </body>
            <body name="lipo_battery_mount-v1" pos="-0.05 -0.02 0.0" euler="-0.0 0.0 1.5707963267948968">
                <geom name="lipo_battery_mount-v1_geom" type="mesh" mesh="lipo_battery_mount-v1" pos="0 0 0" euler="0 0 0" />
                <inertial mass="0.1653518573066047" pos="-4.0023770071114873e-16 -0.003034408758946965 0.003481111705280585" fullinertia="9.882008372625315e-05 7.479150401991051e-05 0.0001696386060861471 4.0216183619824973e-19 -1.283332239482784e-19 2.263422861539775e-06" />
                <body name="Battery---Battery-5.2-Ah-DC5521-Plug-v2" pos="2.220446049250313e-18 0.036499999999999984 0.003000000000000007" euler="-1.5707963267948966 6.123233995736767e-17 -1.5707963267948966">
                    <geom name="Battery---Battery-5.2-Ah-DC5521-Plug-v2_geom" type="mesh" mesh="Battery---Battery-5.2-Ah-DC5521-Plug-v2" pos="0 0 0" euler="0 0 0" />
                    <inertial mass="1.2215469988184764" pos="0.020000000000000018 -8.300646300726007e-05 -0.03492202423172039" fullinertia="0.0008162228074590446 0.00065975897252246 0.00047597821218279645 1.3010426069826053e-18 4.3368086899420163e-19 3.135378714781114e-06" />
                </body>
            </body>
            <body name="94868A713_NO-THREADS_Female-Threaded-Hex-Standoff" pos="0.0 1.3010426069826053e-18 0.025" euler="-0.0 0.0 -0.0">
                <geom name="94868A713_NO-THREADS_Female-Threaded-Hex-Standoff_geom" type="mesh" mesh="94868A713_NO-THREADS_Female-Threaded-Hex-Standoff" pos="0 0 0" euler="0 0 0" />
                <inertial mass="0.006150070863406618" pos="2.1864399078485972e-14 -1.2010287423717232e-09 -6.6970201384464195e-09" fullinertia="1.0965196650850464e-06 1.096519654894581e-06 1.837396493115053e-08 3.0209076389532564e-20 2.6974127807751317e-18 -9.149560120561933e-14" />
            </body>
            <body name="Camera-Mount-v6" pos="-4.551914400963142e-17 0.1 0.0" euler="-0.0 0.0 1.5707963267948966">
                <geom name="Camera-Mount-v6_geom" type="mesh" mesh="Camera-Mount-v6" pos="0 0 0" euler="0 0 0" />
                <inertial mass="0.09147094298688183" pos="0.0030289224720198397 0.00011242904514014542 0.02064739422580405" fullinertia="3.4924657273467044e-05 1.7958936503269972e-05 1.8461671554877027e-05 -2.8535574628355763e-08 1.483173255618039e-06 1.1115307183257866e-07" />
                <body name="Camera-Model-v3" pos="0.005843306737767851 -6.514592966970533e-17 0.02401122309705938" euler="-9.937525710640365e-31 1.3962634015954634 1.5707963267948966">
                    <geom name="Camera-Model-v3_geom" type="mesh" mesh="Camera-Model-v3" pos="0 0 0" euler="0 0 0" />
                    <inertial mass="0.039920058315088616" pos="0.00011860470791938802 0.00023881874959842783 0.004326318838629241" fullinertia="5.219349028990072e-06 5.305573488496055e-06 7.674281395938296e-06 6.564111916115197e-08 1.3381791184156136e-08 2.6971366213773554e-08" />
                </body>
            </body>
            <body name="94868A713_NO-THREADS_Female-Threaded-Hex-Standoff-1" pos="-0.09660254037844385 0.03267949192431126 0.025" euler="8.164311994315686e-17 0.0 -0.0">
                <geom name="94868A713_NO-THREADS_Female-Threaded-Hex-Standoff-1_geom" type="mesh" mesh="94868A713_NO-THREADS_Female-Threaded-Hex-Standoff-1" pos="0 0 0" euler="0 0 0" />
                <inertial mass="0.006150070863406618" pos="2.1866952693017084e-14 -1.2010287431252216e-09 -6.6970201384464195e-09" fullinertia="1.0965196650850481e-06 1.0965196548945726e-06 1.8373964931137077e-08 3.3881317890172236e-20 2.698646969952201e-18 -9.149560204254155e-14" />
            </body>
            <body name="94868A713_NO-THREADS_Female-Threaded-Hex-Standoff-2" pos="0.02 -0.1 0.025" euler="8.164311994315686e-17 0.0 -0.0">
                <geom name="94868A713_NO-THREADS_Female-Threaded-Hex-Standoff-2_geom" type="mesh" mesh="94868A713_NO-THREADS_Female-Threaded-Hex-Standoff-2" pos="0 0 0" euler="0 0 0" />
                <inertial mass="0.006150070863406618" pos="2.1862511800918584e-14 -1.2010287342434374e-09 -6.6970201384464195e-09" fullinertia="1.096519665085043e-06 1.0965196548945802e-06 1.837396493115063e-08 3.2187251995663636e-20 2.6969529040576923e-18 -9.14956011955086e-14" />
            </body>
            <body name="94868A713_NO-THREADS_Female-Threaded-Hex-Standoff-3" pos="0.0766025403784439 0.06732050807568875 0.025" euler="8.164311994315686e-17 0.0 -0.0">
                <geom name="94868A713_NO-THREADS_Female-Threaded-Hex-Standoff-3_geom" type="mesh" mesh="94868A713_NO-THREADS_Female-Threaded-Hex-Standoff-3" pos="0 0 0" euler="0 0 0" />
                <inertial mass="0.006150070863406618" pos="2.1866952693017084e-14 -1.2010287342434374e-09 -6.6970201384464195e-09" fullinertia="1.096519665085043e-06 1.0965196548945862e-06 1.8373964931164182e-08 2.7105054312137834e-20 2.6969529040576923e-18 -9.149559950144271e-14" />
            </body>
        </body>
        <body name="base_plate_layer2-v1" pos="0.0 -6.430841866638185e-19 0.056999999999999995" euler="-0.0 0.0 -0.0">
            <geom name="base_plate_layer2-v1_geom" type="mesh" mesh="base_plate_layer2-v1" pos="0 0 0" euler="0 0 0" />
            <inertial mass="1.9468624348344596" pos="-4.730687660675253e-15 -2.7155537377808555e-05 -0.0034999999999999966" fullinertia="0.0056371098888090545 0.005628440956780792 0.0112496514690387 1.3447333053523506e-16 1.7848833522266602e-20 0.0" />
            <body name="Bottom-V2-v3" pos="-2.980230284777008e-11 -0.06400000000000002 1.4210854715202004e-16" euler="-2.2293090993986824e-33 9.57182296485495e-19 -3.141592653589793">
                <geom name="Bottom-V2-v3_geom" type="mesh" mesh="Bottom-V2-v3" pos="0 0 0" euler="0 0 0" />
                <inertial mass="0.14588862570926195" pos="-0.00162379917481353 0.0017514442972537737 0.0028600223736592917" fullinertia="5.861212367196976e-05 0.000126485904877694 0.00018209683987627657 1.504419769130799e-06 2.5907710844293906e-06 -7.708271472892189e-07" />
                <body name="Top-V2-v2" pos="-2.2605506554644607e-07 0.0 0.02899957050948762" euler="-3.141592653589793 -9.571822964854947e-19 -5.551115123126053e-17">
                    <geom name="Top-V2-v2_geom" type="mesh" mesh="Top-V2-v2" pos="0 0 0" euler="0 0 0" />
                    <inertial mass="0.1256590419653392" pos="-0.0036436981408919968 -0.0003259633563240798 0.004946871759115404" fullinertia="5.8982381320791524e-05 0.00013338786905954623 0.00018586375094365218 1.6170683703385845e-07 2.7949770042390678e-06 -5.073018525688329e-07" />
                </body>
            </body>
        </body>
        <body name="drive_motor_mount-v4" pos="-0.020610000007450578 -0.09 0.0020000000000000018" euler="-0.0 0.0 -1.5707963267948966">
            <geom name="drive_motor_mount-v4_geom" type="mesh" mesh="drive_motor_mount-v4" pos="0 0 0" euler="0 0 0" />
            <inertial mass="0.035884017191401885" pos="0.00017900181977195112 -0.0006914486154622601 0.0004348187449640745" fullinertia="3.2235542654871883e-06 3.901284246443171e-06 6.890721819180175e-06 -1.4488185386067676e-08 -3.4701845947883736e-08 1.0877684749210782e-07" />
        </body>
    </worldbody>
</mujoco>